<mujoco model="dal_quadruped">

  <compiler angle="radian" autolimits="true"/>

  <option timestep="0.002" gravity="0 0 -9.81" integrator="RK4"/>

  <!--
    Dal Robotics Quadruped -- placeholder model for Phase 2.
    Dimensions are approximate (MIT Mini Cheetah scale).
    Update link lengths and masses once Mechanical team provides CAD data.

    Joint naming matches architecture.md motor ID table:
      FL = Front Left    FR = Front Right
      RL = Rear Left     RR = Rear Right
      hip_ab  = Hip Abduction/Adduction (axis: x)
      hip_fe  = Hip Flexion/Extension   (axis: y)
      knee    = Knee                    (axis: y)
  -->

  <default>
    <joint damping="0.2" armature="0.01" frictionloss="0.1"/>
    <geom conaffinity="1" condim="3" friction="0.8 0.005 0.0001"/>
    <motor ctrllimited="true" ctrlrange="-18 18" gear="1"/>
  </default>

  <asset>
    <texture name="floor_tex" type="2d" builtin="checker"
             width="512" height="512"
             rgb1="0.55 0.55 0.55" rgb2="0.45 0.45 0.45"/>
    <material name="floor_mat" texture="floor_tex" texrepeat="6 6" reflectance="0.05"/>
    <material name="body_mat"  rgba="0.25 0.35 0.75 1"/>
    <material name="thigh_mat" rgba="0.65 0.65 0.70 1"/>
    <material name="shank_mat" rgba="0.50 0.50 0.55 1"/>
    <material name="foot_mat"  rgba="0.10 0.10 0.10 1"/>
  </asset>

  <worldbody>
    <light name="main_light"  pos="0 0 4"   dir="0 0 -1"   diffuse="0.7 0.7 0.7" specular="0.1 0.1 0.1"/>
    <light name="fill_light"  pos="2 2 2"   dir="-1 -1 -1" diffuse="0.3 0.3 0.3"/>
    <light name="back_light"  pos="-2 -2 2" dir="1 1 -1"   diffuse="0.2 0.2 0.2"/>

    <geom name="floor" type="plane" size="6 6 0.1" material="floor_mat"/>

    <!-- ================================================================
         TORSO
         Free joint = floating base (6 DOF). Replaced with a fixed joint
         once the robot is attached to a stand for single-motor testing.
         ================================================================ -->
    <body name="torso" pos="0 0 0.35">
      <freejoint name="root"/>
      <geom name="torso_geom" type="box" size="0.19 0.08 0.045" material="body_mat"/>
      <site name="imu" pos="0 0 0" size="0.005"/>

      <!-- ============================================================
           FRONT LEFT LEG
           ============================================================ -->
      <body name="FL_hip_housing" pos="0.15 0.09 0">
        <joint name="FL_hip_ab" type="hinge" axis="1 0 0" range="-0.8 0.8"/>
        <geom type="capsule" size="0.018" fromto="0 0 0 0 0.04 0" material="thigh_mat"/>
        <body name="FL_thigh" pos="0 0.04 0">
          <joint name="FL_hip_fe" type="hinge" axis="0 1 0" range="-1.57 1.57"/>
          <geom type="capsule" size="0.018" fromto="0 0 0 0 0 -0.209" material="thigh_mat"/>
          <body name="FL_shank" pos="0 0 -0.209">
            <joint name="FL_knee" type="hinge" axis="0 1 0" range="-2.6 -0.1"/>
            <geom type="capsule" size="0.013" fromto="0 0 0 0 0 -0.195" material="shank_mat"/>
            <body name="FL_foot" pos="0 0 -0.195">
              <geom name="FL_foot_geom" type="sphere" size="0.022" material="foot_mat"/>
            </body>
          </body>
        </body>
      </body>

      <!-- ============================================================
           FRONT RIGHT LEG
           ============================================================ -->
      <body name="FR_hip_housing" pos="0.15 -0.09 0">
        <joint name="FR_hip_ab" type="hinge" axis="1 0 0" range="-0.8 0.8"/>
        <geom type="capsule" size="0.018" fromto="0 0 0 0 -0.04 0" material="thigh_mat"/>
        <body name="FR_thigh" pos="0 -0.04 0">
          <joint name="FR_hip_fe" type="hinge" axis="0 1 0" range="-1.57 1.57"/>
          <geom type="capsule" size="0.018" fromto="0 0 0 0 0 -0.209" material="thigh_mat"/>
          <body name="FR_shank" pos="0 0 -0.209">
            <joint name="FR_knee" type="hinge" axis="0 1 0" range="-2.6 -0.1"/>
            <geom type="capsule" size="0.013" fromto="0 0 0 0 0 -0.195" material="shank_mat"/>
            <body name="FR_foot" pos="0 0 -0.195">
              <geom name="FR_foot_geom" type="sphere" size="0.022" material="foot_mat"/>
            </body>
          </body>
        </body>
      </body>

      <!-- ============================================================
           REAR LEFT LEG
           ============================================================ -->
      <body name="RL_hip_housing" pos="-0.15 0.09 0">
        <joint name="RL_hip_ab" type="hinge" axis="1 0 0" range="-0.8 0.8"/>
        <geom type="capsule" size="0.018" fromto="0 0 0 0 0.04 0" material="thigh_mat"/>
        <body name="RL_thigh" pos="0 0.04 0">
          <joint name="RL_hip_fe" type="hinge" axis="0 1 0" range="-1.57 1.57"/>
          <geom type="capsule" size="0.018" fromto="0 0 0 0 0 -0.209" material="thigh_mat"/>
          <body name="RL_shank" pos="0 0 -0.209">
            <joint name="RL_knee" type="hinge" axis="0 1 0" range="-2.6 -0.1"/>
            <geom type="capsule" size="0.013" fromto="0 0 0 0 0 -0.195" material="shank_mat"/>
            <body name="RL_foot" pos="0 0 -0.195">
              <geom name="RL_foot_geom" type="sphere" size="0.022" material="foot_mat"/>
            </body>
          </body>
        </body>
      </body>

      <!-- ============================================================
           REAR RIGHT LEG
           ============================================================ -->
      <body name="RR_hip_housing" pos="-0.15 -0.09 0">
        <joint name="RR_hip_ab" type="hinge" axis="1 0 0" range="-0.8 0.8"/>
        <geom type="capsule" size="0.018" fromto="0 0 0 0 -0.04 0" material="thigh_mat"/>
        <body name="RR_thigh" pos="0 -0.04 0">
          <joint name="RR_hip_fe" type="hinge" axis="0 1 0" range="-1.57 1.57"/>
          <geom type="capsule" size="0.018" fromto="0 0 0 0 0 -0.209" material="thigh_mat"/>
          <body name="RR_shank" pos="0 0 -0.209">
            <joint name="RR_knee" type="hinge" axis="0 1 0" range="-2.6 -0.1"/>
            <geom type="capsule" size="0.013" fromto="0 0 0 0 0 -0.195" material="shank_mat"/>
            <body name="RR_foot" pos="0 0 -0.195">
              <geom name="RR_foot_geom" type="sphere" size="0.022" material="foot_mat"/>
            </body>
          </body>
        </body>
      </body>

    </body>
  </worldbody>

  <!-- ================================================================
       ACTUATORS  (one per joint, torque-controlled, matches AK40-10)
       ctrlrange = -18 to +18 Nm (AK40-10 continuous torque limit)
       ================================================================ -->
  <actuator>
    <motor name="FL_hip_ab_act" joint="FL_hip_ab"/>
    <motor name="FL_hip_fe_act" joint="FL_hip_fe"/>
    <motor name="FL_knee_act"   joint="FL_knee"/>
    <motor name="FR_hip_ab_act" joint="FR_hip_ab"/>
    <motor name="FR_hip_fe_act" joint="FR_hip_fe"/>
    <motor name="FR_knee_act"   joint="FR_knee"/>
    <motor name="RL_hip_ab_act" joint="RL_hip_ab"/>
    <motor name="RL_hip_fe_act" joint="RL_hip_fe"/>
    <motor name="RL_knee_act"   joint="RL_knee"/>
    <motor name="RR_hip_ab_act" joint="RR_hip_ab"/>
    <motor name="RR_hip_fe_act" joint="RR_hip_fe"/>
    <motor name="RR_knee_act"   joint="RR_knee"/>
  </actuator>

  <!-- IMU sensors on torso -->
  <sensor>
    <accelerometer name="imu_accel" site="imu"/>
    <gyro          name="imu_gyro"  site="imu"/>
  </sensor>

  <!-- Standing pose keyframe -->
  <keyframe>
    <key name="stand"
         qpos="0 0 0.32
               1 0 0 0
               0  0.65 -1.3
               0  0.65 -1.3
               0  0.65 -1.3
               0  0.65 -1.3"
         ctrl="0 0 0  0 0 0  0 0 0  0 0 0"/>
  </keyframe>

</mujoco>
